Workbook
Name Advance_Formulas: Task_4!$A$1:$H$26
Name NativeTimeline_Date: #N/A
Name Slicer_Payment_Method: #N/A
Name Slicer_Product_Category: #N/A
Name Slicer_Region: #N/A

Sheet Online Sales Data
A1: Transaction ID | B1: Date | C1: Product Category | D1: Product Name | E1: Units Sold | F1: Unit Price | G1: Total Revenue | H1: Region | I1: Payment Method
A2: 10001 | B2: 45292 | C2: Electronics | D2: iPhone 14 Pro | E2: 2 | F2: 999.99 | G2: 1999.98 | H2: North America | I2: Credit Card
A3: 10002 | B3: 45293 | C3: Home Appliances | D3: Dyson V11 Vacuum | E3: 1 | F3: 499.99 | G3: 499.99 | H3: Europe | I3: PayPal
A4: 10003 | B4: 45294 | C4: Clothing | D4: Levi's 501 Jeans | E4: 3 | F4: 69.99 | G4: 209.97 | H4: Asia | I4: Debit Card
A5: 10004 | B5: 45295 | C5: Books | D5: The Da Vinci Code | E5: 4 | F5: 15.99 | G5: 63.96 | H5: North America | I5: Credit Card
A6: 10005 | B6: 45296 | C6: Beauty Products | D6: Neutrogena Skincare Set | E6: 1 | F6: 89.99 | G6: 89.99 | H6: Europe | I6: PayPal
A7: 10006 | B7: 45297 | C7: Sports | D7: Wilson Evolution Basketball | E7: 5 | F7: 29.99 | G7: 149.95 | H7: Asia | I7: Credit Card
A8: 10007 | B8: 45298 | C8: Electronics | D8: MacBook Pro 16-inch | E8: 1 | F8: 2499.99 | G8: 2499.99 | H8: North America | I8: Credit Card
A9: 10008 | B9: 45299 | C9: Home Appliances | D9: Blueair Classic 480i | E9: 2 | F9: 599.99 | G9: 1199.98 | H9: Europe | I9: PayPal
A10: 10009 | B10: 45300 | C10: Clothing | D10: Nike Air Force 1 | E10: 6 | F10: 89.99 | G10: 539.94 | H10: Asia | I10: Debit Card
A11: 10010 | B11: 45301 | C11: Books | D11: Dune by Frank Herbert | E11: 2 | F11: 25.99 | G11: 51.98 | H11: North America | I11: Credit Card
A12: 10011 | B12: 45302 | C12: Beauty Products | D12: Chanel No. 5 Perfume | E12: 1 | F12: 129.99 | G12: 129.99 | H12: Europe | I12: PayPal
A13: 10012 | B13: 45303 | C13: Sports | D13: Babolat Pure Drive Tennis Racket | E13: 3 | F13: 199.99 | G13: 599.97 | H13: Asia | I13: Credit Card
... A241: 10240 | B241: 45531 | C241: Sports | D241: Yeti Rambler 20 oz Tumbler | E241: 2 | F241: 29.99 | G241: 59.98 | H241: Asia | I241: Credit Card

Sheet Task_4
A1: Product Name | B1: Product Category | C1: VLOOKUP | D1: INDEX-MATCH | E1: Total Revenue | F1: IF | G1: Nested IF | H1: AND + IF | J1: Color Legend
A2: iPhone 14 Pro | B2: Electronics | C2: =VLOOKUP(A2,$A$2:$B$26,2,FALSE) -> Electronics | D2: =INDEX($B$2:$B$26,MATCH(A2,$A$2:$A$26,0)) -> Electronics | E2: 1999.98 | F2: =IF(E2>=1000,"High","Low") -> High | G2: =IF(E2>=2000,"A",IF(E2>=1000,"B",IF(E2>=500,"C","D"))) -> B | H2: =IF(AND(E2>=1000,E2<=3000),"Target Achieved","Below Target") -> Target Achieved | J2: Color | K2: Meaning
A3: Dyson V11 Vacuum | B3: Home Appliances | C3: =VLOOKUP(A3,$A$2:$B$26,2,FALSE) -> Home Appliances | D3: =INDEX($B$2:$B$26,MATCH(A3,$A$2:$A$26,0)) -> Home Appliances | E3: 499.99 | F3: =IF(E3>=1000,"High","Low") -> Low | G3: =IF(E3>=2000,"A",IF(E3>=1000,"B",IF(E3>=500,"C","D"))) -> D | H3: =IF(AND(E3>=1000,E3<=3000),"Target Achieved","Below Target") -> Below Target | J3: Light Green | K3: High Revenue / Target Achieved
A4: Levi's 501 Jeans | B4: Clothing | C4: =VLOOKUP(A4,$A$2:$B$26,2,FALSE) -> Clothing | D4: =INDEX($B$2:$B$26,MATCH(A4,$A$2:$A$26,0)) -> Clothing | E4: 209.97 | F4: =IF(E4>=1000,"High","Low") -> Low | G4: =IF(E4>=2000,"A",IF(E4>=1000,"B",IF(E4>=500,"C","D"))) -> D | H4: =IF(AND(E4>=1000,E4<=3000),"Target Achieved","Below Target") -> Below Target | J4: Light Yellow | K4: Grade B
A5: The Da Vinci Code | B5: Books | C5: =VLOOKUP(A5,$A$2:$B$26,2,FALSE) -> Books | D5: =INDEX($B$2:$B$26,MATCH(A5,$A$2:$A$26,0)) -> Books | E5: 63.96 | F5: =IF(E5>=1000,"High","Low") -> Low | G5: =IF(E5>=2000,"A",IF(E5>=1000,"B",IF(E5>=500,"C","D"))) -> D | H5: =IF(AND(E5>=1000,E5<=3000),"Target Achieved","Below Target") -> Below Target | J5: Light Blue | K5: Grade C
A6: Neutrogena Skincare Set | B6: Beauty Products | C6: =VLOOKUP(A6,$A$2:$B$26,2,FALSE) -> Beauty Products | D6: =INDEX($B$2:$B$26,MATCH(A6,$A$2:$A$26,0)) -> Beauty Products | E6: 89.99 | F6: =IF(E6>=1000,"High","Low") -> Low | G6: =IF(E6>=2000,"A",IF(E6>=1000,"B",IF(E6>=500,"C","D"))) -> D | H6: =IF(AND(E6>=1000,E6<=3000),"Target Achieved","Below Target") -> Below Target | J6: Light Red | K6: Grade D
A7: Wilson Evolution Basketball | B7: Sports | C7: =VLOOKUP(A7,$A$2:$B$26,2,FALSE) -> Sports | D7: =INDEX($B$2:$B$26,MATCH(A7,$A$2:$A$26,0)) -> Sports | E7: 149.95 | F7: =IF(E7>=1000,"High","Low") -> Low | G7: =IF(E7>=2000,"A",IF(E7>=1000,"B",IF(E7>=500,"C","D"))) -> D | H7: =IF(AND(E7>=1000,E7<=3000),"Target Achieved","Below Target") -> Below Target | J7: White | K7: Normal Data
A8: MacBook Pro 16-inch | B8: Electronics | C8: =VLOOKUP(A8,$A$2:$B$26,2,FALSE) -> Electronics | D8: =INDEX($B$2:$B$26,MATCH(A8,$A$2:$A$26,0)) -> Electronics | E8: 2499.99 | F8: =IF(E8>=1000,"High","Low") -> High | G8: =IF(E8>=2000,"A",IF(E8>=1000,"B",IF(E8>=500,"C","D"))) -> A | H8: =IF(AND(E8>=1000,E8<=3000),"Target Achieved","Below Target") -> Target Achieved
A9: Blueair Classic 480i | B9: Home Appliances | C9: =VLOOKUP(A9,$A$2:$B$26,2,FALSE) -> Home Appliances | D9: =INDEX($B$2:$B$26,MATCH(A9,$A$2:$A$26,0)) -> Home Appliances | E9: 1199.98 | F9: =IF(E9>=1000,"High","Low") -> High | G9: =IF(E9>=2000,"A",IF(E9>=1000,"B",IF(E9>=500,"C","D"))) -> B | H9: =IF(AND(E9>=1000,E9<=3000),"Target Achieved","Below Target") -> Target Achieved
A10: Nike Air Force 1 | B10: Clothing | C10: =VLOOKUP(A10,$A$2:$B$26,2,FALSE) -> Clothing | D10: =INDEX($B$2:$B$26,MATCH(A10,$A$2:$A$26,0)) -> Clothing | E10: 539.94 | F10: =IF(E10>=1000,"High","Low") -> Low | G10: =IF(E10>=2000,"A",IF(E10>=1000,"B",IF(E10>=500,"C","D"))) -> C | H10: =IF(AND(E10>=1000,E10<=3000),"Target Achieved","Below Target") -> Below Target
A11: Dune by Frank Herbert | B11: Books | C11: =VLOOKUP(A11,$A$2:$B$26,2,FALSE) -> Books | D11: =INDEX($B$2:$B$26,MATCH(A11,$A$2:$A$26,0)) -> Books | E11: 51.98 | F11: =IF(E11>=1000,"High","Low") -> Low | G11: =IF(E11>=2000,"A",IF(E11>=1000,"B",IF(E11>=500,"C","D"))) -> D | H11: =IF(AND(E11>=1000,E11<=3000),"Target Achieved","Below Target") -> Below Target
A12: Chanel No. 5 Perfume | B12: Beauty Products | C12: =VLOOKUP(A12,$A$2:$B$26,2,FALSE) -> Beauty Products | D12: =INDEX($B$2:$B$26,MATCH(A12,$A$2:$A$26,0)) -> Beauty Products | E12: 129.99 | F12: =IF(E12>=1000,"High","Low") -> Low | G12: =IF(E12>=2000,"A",IF(E12>=1000,"B",IF(E12>=500,"C","D"))) -> D | H12: =IF(AND(E12>=1000,E12<=3000),"Target Achieved","Below Target") -> Below Target
A13: Babolat Pure Drive Tennis Racket | B13: Sports | C13: =VLOOKUP(A13,$A$2:$B$26,2,FALSE) -> Sports | D13: =INDEX($B$2:$B$26,MATCH(A13,$A$2:$A$26,0)) -> Sports | E13: 599.97 | F13: =IF(E13>=1000,"High","Low") -> Low | G13: =IF(E13>=2000,"A",IF(E13>=1000,"B",IF(E13>=500,"C","D"))) -> C | H13: =IF(AND(E13>=1000,E13<=3000),"Target Achieved","Below Target") -> Below Target
A14: Samsung Galaxy Tab S8 | B14: Electronics | C14: =VLOOKUP(A14,$A$2:$B$26,2,FALSE) -> Electronics | D14: =INDEX($B$2:$B$26,MATCH(A14,$A$2:$A$26,0)) -> Electronics | E14: 1499.98 | F14: =IF(E14>=1000,"High","Low") -> High | G14: =IF(E14>=2000,"A",IF(E14>=1000,"B",IF(E14>=500,"C","D"))) -> B | H14: =IF(AND(E14>=1000,E14<=3000),"Target Achieved","Below Target") -> Target Achieved
A15: Keurig K-Elite Coffee Maker | B15: Home Appliances | C15: =VLOOKUP(A15,$A$2:$B$26,2,FALSE) -> Home Appliances | D15: =INDEX($B$2:$B$26,MATCH(A15,$A$2:$A$26,0)) -> Home Appliances | E15: 189.99 | F15: =IF(E15>=1000,"High","Low") -> Low | G15: =IF(E15>=2000,"A",IF(E15>=1000,"B",IF(E15>=500,"C","D"))) -> D | H15: =IF(AND(E15>=1000,E15<=3000),"Target Achieved","Below Target") -> Below Target
A16: North Face Down Jacket | B16: Clothing | C16: =VLOOKUP(A16,$A$2:$B$26,2,FALSE) -> Clothing | D16: =INDEX($B$2:$B$26,MATCH(A16,$A$2:$A$26,0)) -> Clothing | E16: 499.98 | F16: =IF(E16>=1000,"High","Low") -> Low | G16: =IF(E16>=2000,"A",IF(E16>=1000,"B",IF(E16>=500,"C","D"))) -> D | H16: =IF(AND(E16>=1000,E16<=3000),"Target Achieved","Below Target") -> Below Target
A17: Salt, Fat, Acid, Heat by Samin Nosrat | B17: Books | C17: =VLOOKUP(A17,$A$2:$B$26,2,FALSE) -> Books | D17: =INDEX($B$2:$B$26,MATCH(A17,$A$2:$A$26,0)) -> Books | E17: 107.97 | F17: =IF(E17>=1000,"High","Low") -> Low | G17: =IF(E17>=2000,"A",IF(E17>=1000,"B",IF(E17>=500,"C","D"))) -> D | H17: =IF(AND(E17>=1000,E17<=3000),"Target Achieved","Below Target") -> Below Target
A18: Dyson Supersonic Hair Dryer | B18: Beauty Products | C18: =VLOOKUP(A18,$A$2:$B$26,2,FALSE) -> Beauty Products | D18: =INDEX($B$2:$B$26,MATCH(A18,$A$2:$A$26,0)) -> Beauty Products | E18: 399.99 | F18: =IF(E18>=1000,"High","Low") -> Low | G18: =IF(E18>=2000,"A",IF(E18>=1000,"B",IF(E18>=500,"C","D"))) -> D | H18: =IF(AND(E18>=1000,E18<=3000),"Target Achieved","Below Target") -> Below Target
A19: Manduka PRO Yoga Mat | B19: Sports | C19: =VLOOKUP(A19,$A$2:$B$26,2,FALSE) -> Sports | D19: =INDEX($B$2:$B$26,MATCH(A19,$A$2:$A$26,0)) -> Sports | E19: 479.96 | F19: =IF(E19>=1000,"High","Low") -> Low | G19: =IF(E19>=2000,"A",IF(E19>=1000,"B",IF(E19>=500,"C","D"))) -> D | H19: =IF(AND(E19>=1000,E19<=3000),"Target Achieved","Below Target") -> Below Target
... A26: Bose QuietComfort 35 Headphones | B26: Electronics | C26: =VLOOKUP(A26,$A$2:$B$26,2,FALSE) -> Electronics | D26: =INDEX($B$2:$B$26,MATCH(A26,$A$2:$A$26,0)) -> Electronics | E26: 299.99 | F26: =IF(E26>=1000,"High","Low") -> Low | G26: =IF(E26>=2000,"A",IF(E26>=1000,"B",IF(E26>=500,"C","D"))) -> D | H26: =IF(AND(E26>=1000,E26<=3000),"Target Achieved","Below Target") -> Below Target

Sheet Pivots & Charts
A1: Product Category | B1: Sum of Total Revenue
A2: Electronics | B2: 34982.41
A3: Home Appliances | B3: 18646.16
A4: Sports | B4: 14326.52
A5: Clothing | B5: 8128.93
A6: Beauty Products | B6: 2621.9
A7: Books | B7: 1861.93
A8: Grand Total | B8: 80567.85
A18: Region | B18: Sum of Total Revenue
A19: North America | B19: 36844.34
A20: Asia | B20: 22455.45
A21: Europe | B21: 21268.06
A22: Grand Total | B22: 80567.85
A35: Payment Method | B35: Sum of Total Revenue
A36: Credit Card | B36: 51170.86
A37: Debit Card | B37: 8128.93
A38: PayPal | B38: 21268.06
A39: Grand Total | B39: 80567.85
A52: Months (Date) | B52: Sum of Total Revenue
A53: Jan | B53: 14548.32
A54: Feb | B54: 10803.37
A55: Mar | B55: 12849.24
A56: Apr | B56: 12451.69
A57: May | B57: 8455.49
A58: Jun | B58: 7384.55
A59: Jul | B59: 6797.08
A60: Aug | B60: 7278.11
A61: Grand Total | B61: 80567.85
A69: Product Name | B69: Sum of Total Revenue
A70: Canon EOS R5 Camera | B70: 3899.99
A71: LG OLED TV | B71: 2599.98
A72: MacBook Pro 16-inch | B72: 2499.99
A73: Apple MacBook Pro 16-inch | B73: 2399
A74: iPhone 14 Pro | B74: 1999.98
A75: Peloton Bike | B75: 1895
A76: HP Spectre x360 Laptop | B76: 1599.99
A77: Roomba i7+ | B77: 1599.98
A78: Garmin Forerunner 945 | B78: 1599.97
A79: Samsung Odyssey G9 Gaming Monitor | B79: 1499.99
A80: Grand Total | B80: 21593.87
...

Sheet Dashboard
E2: Apex Product Analytics Dashboard
A9: Total Revenue
A11: =GETPIVOTDATA("Total Revenue",'Pivots & Charts'!$A$52) -> 80567.85
A16: Total Units Sold
A18: =GETPIVOTDATA("Units Sold",'Pivots & Charts'!$A$86) -> 518
A23: Total Transactions
A25: =GETPIVOTDATA("Count of Transaction ID",'Pivots & Charts'!$A$86) -> 240
A30: Best Category
A32: ='Pivots & Charts'!A2 -> Electronics
A37: Best Region
A39: ='Pivots & Charts'!A19 -> North America
